<?xml version="1.0" ?>
<sdf version="1.7">
  <model name='robot${suffix}'>
    <pose>0.0 0.0 0.1 0 0 0</pose>
    <link name='base_link${suffix}'>
      <collision name='collision'>
        <geometry>
          <box>
            <size>0.13 0.12 0.08</size>
          </box>
        </geometry>
      </collision>
      <inertial>
        <mass>0.55</mass>
        <inertia>
          <ixx>0.0227</ixx>
          <ixy>0</ixy>
          <ixz>0</ixz>
          <iyy>0.0852</iyy>
          <iyz>0</iyz>
          <izz>0.1041</izz>
        </inertia>
        <pose> 0.0 0.0125 0.0 0.0 0.0</pose>
      </inertial>
      <visual name='visual'>
        <geometry>
          <box>
            <size>0.13 0.12 0.08</size>
          </box>
        </geometry>
        <material>
          <diffuse>0.2 0.2 0.2 1</diffuse>
          <ambient>0.2 0.2 0.2 1</ambient>
          <specular>1 1 1 1</specular>
          <emissive>0 0 0 1</emissive>
        </material>
      </visual>
    </link>

    <link name="camera_link">
      <pose>0.07 0.0 0.04 0 0 0</pose>
      <visual name='visual'>
        <geometry>
          <box>
            <size>0.02 0.02 0.02</size>
          </box>
        </geometry>
        <material>
          <diffuse>1 0 0 1</diffuse>
          <ambient>1 1 0 1</ambient>
          <specular>1 1 1 1</specular>
          <emissive>0 1 0 1</emissive>
        </material>
      </visual>
      <collision name='collision'>
        <geometry>
          <box>
            <size>0.02 0.02 0.02</size>
          </box>
        </geometry>
      </collision>
      <inertial>
        <mass>0.55</mass>
        <inertia>
          <ixx>0.0227</ixx>
          <ixy>0</ixy>
          <ixz>0</ixz>
          <iyy>0.0852</iyy>
          <iyz>0</iyz>
          <izz>0.1041</izz>
        </inertia>
      </inertial>

      <sensor type="camera" name="sensor_cam">
        <pose>0.02 0 0 0 0 0</pose>
        <visualize>false</visualize>
        <always_on>1</always_on>
        <update_rate>1</update_rate>

        <camera name="camera">
          <distortion>
            <k1>0</k1>
            <k2>0</k2>
            <k3>0</k3>
            <p1>0</p1>
            <p2>0</p2>
            <center>0.5 0.5</center>
          </distortion>
          <image>
            <width>1920</width>
            <height>1080</height>
            <format>R8G8B8</format>
          </image>
        </camera>

        <plugin name="ros_camera" filename="libgazebo_ros_camera.so">

          <cameraName>camera</cameraName>

          <imageTopicName>image_raw</imageTopicName>
          <cameraInfoTopicName>camera_info</cameraInfoTopicName>

          <frameName>odom</frameName>

          <hack_baseline>0.07</hack_baseline>
        </plugin>
      </sensor>
    </link>

    <joint name='camera_joint' type='fixed'>
      <parent>base_link${suffix}</parent>
      <child>camera_link</child>
    </joint>

    <!-- Ultrasonic element -->
    <link name="ultrasonic_link">
      <pose>0.07 0.0 0.0 0 0 0</pose>
      <visual name='visual'>
        <geometry>
          <box>
            <size>0.011 0.04 0.02</size>
          </box>
        </geometry>
        <material>
          <ambient>0 0 0 0.2</ambient>
        </material>
      </visual>
      <visual name='visual_p1'>
        <pose>0.005 -0.007 0.0 0 0 0</pose>
        <geometry>
          <sphere>
            <radius>0.004</radius>
          </sphere>
        </geometry>
        <material>
          <diffuse>0 0 1 1</diffuse>
          <ambient>0 0 1 1</ambient>
          <specular>1 1 1 1</specular>
          <emissive>0 0 1 1</emissive>
        </material>
      </visual>
      <visual name='visual_p2'>
        <pose>0.005 0.007 0.0 0 0 0</pose>
        <geometry>
          <sphere>
            <radius>0.004</radius>
          </sphere>
        </geometry>
        <material>
          <diffuse>0 0 1 1</diffuse>
          <ambient>0 0 1 1</ambient>
          <specular>1 1 1 1</specular>
          <emissive>0 0 1 1</emissive>
        </material>
      </visual>
      <collision name='collision'>
        <geometry>
          <box>
            <size>0.012 0.04 0.02</size>
          </box>
        </geometry>
      </collision>
      <inertial>
        <mass>0.55</mass>
        <inertia>
          <ixx>0.0227</ixx>
          <ixy>0</ixy>
          <ixz>0</ixz>
          <iyy>0.0852</iyy>
          <iyz>0</iyz>
          <izz>0.1041</izz>
        </inertia>
      </inertial>

      <sensor name="sensor_ray" type="ray">
        <pose>0.001 0 0 0 0 0</pose>
        <ray>
          <scan>
            <horizontal>
              <samples>200</samples>
              <resolution>1.0</resolution>
              <min_angle>-0.25</min_angle>
              <max_angle>0.25</max_angle>
            </horizontal>
          </scan>
          <range>
            <min>0.03</min>
            <max>4.0</max>
          </range>
        </ray>
        <always_on>true</always_on>
        <visualize>true</visualize>
        <update_rate>100.0</update_rate>
        <plugin name="range" filename="libgazebo_ros_laser.so">
          <topicName>scan</topicName>
          <frameName>odom</frameName>
        </plugin>
        <plugin name="laser" filename="libgazebo_ros_laser.so">
          <topicName>scan</topicName>
          <frameName>odom</frameName>
        </plugin>
      </sensor>
    </link>

    <joint name='ultrasonic_joint' type='fixed'>
      <parent>base_link${suffix}</parent>
      <child>ultrasonic_link</child>
    </joint>

    <link name='left_wheel'>
      <pose>0.06 0.06 -0.05 1.5708 0 0</pose>
      <inertial>
        <mass>0.5</mass>
        <inertia>
          <ixx>0.0029</ixx>
          <ixy>0</ixy>
          <ixz>0</ixz>
          <iyy>0.0029</iyy>
          <iyz>0</iyz>
          <izz>0.0056</izz>
        </inertia>
      </inertial>
      <visual name='visual'>
        <geometry>
          <cylinder>
            <radius>0.0325</radius>
            <length>0.025</length>
          </cylinder>
        </geometry>
        <material>
          <diffuse>1 1 1 1</diffuse>
          <ambient>0 0 0 1</ambient>
          <specular>1 1 1 1</specular>
          <emissive>0 0 0 1</emissive>
        </material>
      </visual>
      <collision name='collision'>
        <geometry>
          <sphere>
            <radius>0.0325</radius>
          </sphere>
        </geometry>
        <surface>
          <friction>
            <ode>
              <mu>1</mu>
              <mu2>1</mu2>
              <slip1>0</slip1>
              <slip2>0</slip2>
            </ode>
          </friction>
          <contact>
            <ode>
              <soft_cfm>0</soft_cfm>
              <soft_erp>0.2</soft_erp>
              <kp>1e+13</kp>
              <kd>1</kd>
              <max_vel>0.01</max_vel>
              <min_depth>0.01</min_depth>
            </ode>
          </contact>
        </surface>
      </collision>
    </link>

    <link name='right_wheel'>
      <pose>0.06 -0.06 -0.05 1.5708 0 0</pose>
      <inertial>
        <mass>0.5</mass>
        <inertia>
          <ixx>0.0029</ixx>
          <ixy>0</ixy>
          <ixz>0</ixz>
          <iyy>0.0029</iyy>
          <iyz>0</iyz>
          <izz>0.0056</izz>
        </inertia>
      </inertial>
      <visual name='visual'>
        <geometry>
          <cylinder>
            <radius>0.0325</radius>
            <length>0.025</length>
          </cylinder>
        </geometry>
        <material>
          <diffuse>1 1 1 1</diffuse>
          <ambient>0 0 0 1</ambient>
          <specular>1 1 1 1</specular>
          <emissive>0 0 0 1</emissive>
        </material>
      </visual>
      <collision name='collision'>
        <geometry>
          <sphere>
            <radius>0.0325</radius>
          </sphere>
        </geometry>
        <surface>
          <friction>
            <ode>
              <mu>1</mu>
              <mu2>1</mu2>
              <slip1>0</slip1>
              <slip2>0</slip2>
            </ode>
          </friction>
          <contact>
            <ode>
              <soft_cfm>0</soft_cfm>
              <soft_erp>0.2</soft_erp>
              <kp>1e+13</kp>
              <kd>1</kd>
              <max_vel>0.01</max_vel>
              <min_depth>0.01</min_depth>
            </ode>
          </contact>
        </surface>
      </collision>
    </link>


    <joint name='left_wheel_joint' type='revolute'>
      <parent>base_link${suffix}</parent>
      <child>left_wheel</child>
      <axis>
        <xyz>0 0 -1</xyz>
        <limit>
          <lower>-1.79769e+308</lower>
          <upper>1.79769e+308</upper>
        </limit>
      </axis>
    </joint>

    <joint name='right_wheel_joint' type='revolute'>
      <parent>base_link${suffix}</parent>
      <child>right_wheel</child>
      <axis>
        <xyz>0 0 -1</xyz>
        <limit>
          <lower>-1.79769e+308</lower>
          <upper>1.79769e+308</upper>
        </limit>
      </axis>
    </joint>

    <!-- 2 wheels more-->
    <link name='left_wheel_2'>
      <pose>-0.06 0.06 -0.05 1.5708 0 0</pose>
      <inertial>
        <mass>0.5</mass>
        <inertia>
          <ixx>0.0029</ixx>
          <ixy>0</ixy>
          <ixz>0</ixz>
          <iyy>0.0029</iyy>
          <iyz>0</iyz>
          <izz>0.0056</izz>
        </inertia>
      </inertial>
      <visual name='visual'>
        <geometry>
          <cylinder>
            <radius>0.0325</radius>
            <length>0.025</length>
          </cylinder>
        </geometry>
        <material>
          <diffuse>1 1 1 1</diffuse>
          <ambient>0 0 0 1</ambient>
          <specular>1 1 1 1</specular>
          <emissive>0 0 0 1</emissive>
        </material>
      </visual>
      <collision name='collision'>
        <geometry>
          <sphere>
            <radius>0.0325</radius>
          </sphere>
        </geometry>
        <surface>
          <friction>
            <ode>
              <mu>1</mu>
              <mu2>1</mu2>
              <slip1>0</slip1>
              <slip2>0</slip2>
            </ode>
          </friction>
          <contact>
            <ode>
              <soft_cfm>0</soft_cfm>
              <soft_erp>0.2</soft_erp>
              <kp>1e+13</kp>
              <kd>1</kd>
              <max_vel>0.01</max_vel>
              <min_depth>0.01</min_depth>
            </ode>
          </contact>
        </surface>
      </collision>
    </link>

    <link name='right_wheel_2'>
      <pose>-0.06 -0.06 -0.05 1.5708 0 0</pose>
      <inertial>
        <mass>0.5</mass>
        <inertia>
          <ixx>0.0029</ixx>
          <ixy>0</ixy>
          <ixz>0</ixz>
          <iyy>0.0029</iyy>
          <iyz>0</iyz>
          <izz>0.0056</izz>
        </inertia>
      </inertial>
      <visual name='visual'>
        <geometry>
          <cylinder>
            <radius>0.0325</radius>
            <length>0.025</length>
          </cylinder>
        </geometry>
        <material>
          <diffuse>1 1 1 1</diffuse>
          <ambient>0 0 0 1</ambient>
          <specular>1 1 1 1</specular>
          <emissive>0 0 0 1</emissive>
        </material>
      </visual>
      <collision name='collision'>
        <geometry>
          <sphere>
            <radius>0.0325</radius>
          </sphere>
        </geometry>
        <surface>
          <friction>
            <ode>
              <mu>1</mu>
              <mu2>1</mu2>
              <slip1>0</slip1>
              <slip2>0</slip2>
            </ode>
          </friction>
          <contact>
            <ode>
              <soft_cfm>0</soft_cfm>
              <soft_erp>0.2</soft_erp>
              <kp>1e+13</kp>
              <kd>1</kd>
              <max_vel>0.01</max_vel>
              <min_depth>0.01</min_depth>
            </ode>
          </contact>
        </surface>
      </collision>
    </link>

    <joint name='left_wheel_joint_2' type='revolute'>
      <parent>base_link${suffix}</parent>
      <child>left_wheel_2</child>
      <axis>
        <xyz>0 0 -1</xyz>
        <limit>
          <lower>-1.79769e+308</lower>
          <upper>1.79769e+308</upper>
        </limit>
      </axis>
    </joint>

    <joint name='right_wheel_joint_2' type='revolute'>
      <parent>base_link${suffix}</parent>
      <child>right_wheel_2</child>
      <axis>
        <xyz>0 0 -1</xyz>
        <limit>
          <lower>-1.79769e+308</lower>
          <upper>1.79769e+308</upper>
        </limit>
      </axis>
    </joint>

    <plugin name="front_wheel_plugin" filename="libgazebo_ros_diff_drive.so">
      <leftJoint>left_wheel_joint</leftJoint>
      <rightJoint>right_wheel_joint</rightJoint>
      <wheelSeparation>0.150</wheelSeparation>
      <wheelDiameter>0.065</wheelDiameter>
      <wheelAcceleration>1.0</wheelAcceleration>
      <wheelTorque>20</wheelTorque>
      <odometryFrame>odom</odometryFrame>
      <robotBaseFrame>base_link${suffix}</robotBaseFrame>
      <publishWheelTF>true</publishWheelTF>
      <publishOdom>true</publishOdom>
      <publishWheelJointState>true</publishWheelJointState>
    </plugin>

    <plugin name="rear_wheel_plugin" filename="libgazebo_ros_diff_drive.so">
      <leftJoint>left_wheel_joint_2</leftJoint>
      <rightJoint>right_wheel_joint_2</rightJoint>
      <wheelSeparation>0.150</wheelSeparation>
      <wheelDiameter>0.065</wheelDiameter>
      <wheelAcceleration>1.0</wheelAcceleration>
      <wheelTorque>20</wheelTorque>
      <odometryFrame>odom</odometryFrame>
      <robotBaseFrame>base_link${suffix}</robotBaseFrame>
      <publishWheelTF>true</publishWheelTF>
      <publishOdom>true</publishOdom>
      <publishWheelJointState>true</publishWheelJointState>
    </plugin>

  </model>
</sdf>